Workbook
Name ACTION: #REF!
Name Z_2C0D9096_8D85_462A_A9B5_0B488ADB4269__wvu_PrintArea: 'Test Report'!$A:$I
Name Z_6F1DCD5D_5DAC_4817_BF40_2B66F6F593E6__wvu_PrintArea: 'Test Report'!$A:$I
Name Z_BE54E0AD_3725_4423_92D7_4F1C045BE1BC__wvu_PrintArea: 'Test Report'!$A:$I
Name Z_2C0D9096_8D85_462A_A9B5_0B488ADB4269__wvu_Cols: 'UT Lab 2'!$E:$E
Name Z_6F1DCD5D_5DAC_4817_BF40_2B66F6F593E6__wvu_Cols: 'UT Lab 2'!$E:$E
Name Z_BE54E0AD_3725_4423_92D7_4F1C045BE1BC__wvu_Cols: 'UT Lab 2'!$E:$E
Name Z_2C0D9096_8D85_462A_A9B5_0B488ADB4269__wvu_Cols: 'UT Lab 3'!$E:$E
Name Z_6F1DCD5D_5DAC_4817_BF40_2B66F6F593E6__wvu_Cols: 'UT Lab 3'!$E:$E
Name Z_BE54E0AD_3725_4423_92D7_4F1C045BE1BC__wvu_Cols: 'UT Lab 3'!$E:$E

Sheet Guidleline
A1: Guideline to make and understand Unit Test Case
A3: 1. Overview
A4: - In the template, Unit test cases are based on functions. Each sheet presents test cases for one function.
A5: - Cover: General information of the project and Unit Test cases
A6: - FunctionList: The list of Classes and Functions in the document. + To control that the number of Unit TC meets customer's requirement or the norm, user should fill value for 'Normal number of Test cases/KLOC'.
A7: + Click on Function link to open the related Test cases of the function. Note: You should create new Function sheet before creating the link
A8: - Test Report: provive the overview results of Functions Unit test: Test coverage, Test successful coverage (Summary, for normal/abnormal/boundary cases)
A9: Note: Should check the formula of "Sub Total" if you add more functions
A11: 2. Content in Test function sheet
A12: 2.1 Combination of test cases.
A13: - To verify that number of Unit TC meets customer's requirement or not. User has to fill number LOC of tested function and fill value of 'Normal number test cases/KLOC' item in FunctionList sheet, which is required by customer or normal value. The number of lacked TC is shown in 'Lack of test cases' item.
A14: - If the number of Unit TC does not meet the requirement, creator should explain the reasons.
... A95: - Yêu cầu kiểm tra: Mô tả ngắn gọn về các yêu cầu được kiểm tra trong chức năng này, nó không bắt buộc.

Sheet Cover
B2: UNIT TEST CASE
A4: Project Name | B4: SmartOTT | E4: Creator | F4: Nhóm 10: Phạm Như Ý, Nguyễn Danh Minh Toàn, Trần Quốc Đảm
A5: Project Code | B5: Module01 | E5: Reviewer/Approver | F5: Tester: Phạm Như Ý
A6: Document Code | E6: Issue Date | F6: 30/11/2020
E7: Version | F7: 1
A10: Record of change
A11: Effective Date | B11: Version | C11: Change Item | D11: *A,D,M | E11: Change description | F11: Reference
A12: 30/11/2020 | B12: 0.1 | D12: A | E12: Create new unit test | F12: <List of documents which are refered in this version.>
A13: 18/12/2020 | B13: 1.0 | D13: A | E13: execute unit test

Sheet FunctionList
E2: UNIT TEST CASE LIST
A4: Project Name | E4: SmartOTT
A5: Project Code | E5: Module01
A6: Normal number of Test cases/KLOC | E6: 8
A7: Test Environment Setup Description | E7: Sử dụng kết nối mạng 1. Server 2. Database 3. Web Browser ... >
A10: No | B10: Requirement Name | C10: Class Name | D10: Function Name | E10: Function Code(Optional) | F10: Sheet Name | G10: Description | H10: Pre-Condition
A11: 1 | B11: Kiểm chứng đăng nhập, đăng xuất và bảo vệ route | C11: Auth | D11: Login/Logout | E11: AUTH | F11: UT Lab 1 | G11: Nguyễn Danh Minh Toàn | H11: BE, FE, DB chạy; tài khoản user: nhuy02042003@gmail.com / 123456; tài khoản admin/page admin: mon02050703@gmail.com / 123456
A12: 2 | B12: Kiểm chứng đăng ký tài khoản bằng email và OTP | C12: Auth | D12: Register OTP | E12: REG | F12: UT Lab 2 | G12: Phạm Như Ý | H12: Email đăng ký mới chưa tồn tại: monne0205@gmail.com; OTP được gửi qua email
A13: 3 | B13: Kiểm chứng quên mật khẩu và đổi mật khẩu | C13: Auth | D13: Forgot/Reset Password | E13: PASS | F13: UT Lab 3 | G13: Phạm Như Ý | H13: Email test tồn tại; mật khẩu mặc định 123456
A14: 4 | B14: Kiểm chứng quản lý thông tin cá nhân, avatar, cover | C14: User | D14: Profile Management | E14: PROFILE | F14: UT Lab 4 | G14: Phạm Như Ý | H14: Đã đăng nhập user
A15: 5 | B15: Kiểm chứng tìm kiếm bạn bè, gửi/duyệt/hủy kết bạn | C15: Friend | D15: Friend Management | E15: FRIEND | F15: UT Lab 5 | G15: Phạm Như Ý | H15: Ít nhất 2 tài khoản test
A16: 6 | B16: Kiểm chứng chat 1-1 realtime, unread, edit, delete, reaction, reply | C16: Chat | D16: Private Chat | E16: CHAT | F16: UT Lab 6 | G16: Trần Quốc Đảm | H16: Hai tài khoản đã là bạn
A17: 7 | B17: Kiểm chứng chat nhóm: tạo nhóm, thêm/xóa thành viên, giải tán nhóm | C17: Chat | D17: Group Chat | E17: GROUP | F17: UT Lab 7 | G17: Trần Quốc Đảm | H17: 3 tài khoản test
A18: 8 | B18: Kiểm chứng gửi file, ảnh, video, tải xuống, chuyển tiếp tin nhắn | C18: Upload/Chat | D18: File & Forward | E18: FILE | F18: UT Lab 8 | G18: Trần Quốc Đảm | H18: S3/presigned URL hoạt động
A19: 9 | B19: Kiểm chứng gọi audio/video bằng WebRTC/socket | C19: Call | D19: Audio/Video Call | E19: CALL | F19: UT Lab 9 | G19: Cả nhóm | H19: 2-3 trình duyệt hoặc máy khác nhau
A20: 10 | B20: Kiểm chứng Chat AI dịch vụ công, session, fallback khi Gemini lỗi | C20: AI | D20: Public Service AI | E20: AI | F20: UT Lab10 | G20: Trần Quốc Đảm | H20: GEMINI_API_KEY hoặc fallback BE
A21: 11 | B21: Kiểm chứng admin: dashboard, user, group, thống kê, khóa/xóa | C21: Admin | D21: Admin Management | E21: ADMIN | F21: UT Lab11 | G21: Nguyễn Danh Minh Toàn | H21: Đăng nhập admin/page admin: mon02050703@gmail.com / 123456

Sheet Test Report
A2: UNIT TEST REPORT
A4: Project Name | B4: SmartOTT | D4: Creator | F4: Nhóm 10: Phạm Như Ý, Nguyễn Danh Minh Toàn, Trần Quốc Đảm
A5: Project Code | B5: Module01 | D5: Reviewer/Approver | F5: Tester: Phạm Như Ý
A6: Document Code | D6: Issue Date | F6: 30/11/2020
A7: Notes | B7: Release 1 includes : 7 use case , release 2 includes : 11 use case
A11: No | B11: Function code | C11: Passed | D11: Failed | E11: Untested | F11: N | G11: A | H11: B | I11: Total Test Cases
A12: 1 | B12: UT Lab 1 | C12: ='UT Lab 1'!A7 -> 9 | D12: ='UT Lab 1'!C7 -> 0 | E12: ='UT Lab 1'!F7 -> 0 | F12: ='UT Lab 1'!L7 -> 9 | G12: ='UT Lab 1'!M7 -> 0 | H12: ='UT Lab 1'!N7 -> 0 | I12: ='UT Lab 1'!O7 -> 9
A13: 2 | B13: UT Lab 2 | C13: ='UT Lab 2'!A7 -> 1 | D13: ='UT Lab 2'!C7 -> 6 | E13: ='UT Lab 2'!F7 -> 0 | F13: ='UT Lab 2'!L7 -> 7 | G13: ='UT Lab 2'!M7 -> 0 | H13: ='UT Lab 2'!N7 -> 0 | I13: ='UT Lab 2'!O7 -> 7
A14: 3 | B14: UT Lab 3 | C14: ='UT Lab 3'!A7 -> 1 | D14: ='UT Lab 3'!C7 -> 2 | E14: ='UT Lab 3'!F7 -> 0 | F14: ='UT Lab 3'!L7 -> 3 | G14: ='UT Lab 3'!M7 -> 0 | H14: ='UT Lab 3'!N7 -> 0 | I14: ='UT Lab 3'!O7 -> 3
A15: 4 | B15: UT Lab 4 | C15: ='UT Lab 4'!A7 -> 1 | D15: ='UT Lab 4'!C7 -> 2 | E15: ='UT Lab 4'!F7 -> 0 | F15: ='UT Lab 4'!L7 -> 3 | G15: ='UT Lab 4'!M7 -> 0 | H15: ='UT Lab 4'!N7 -> 0 | I15: ='UT Lab 4'!O7 -> 3
A16: 5 | B16: UT Lab 5 | C16: ='UT Lab 5'!A7 -> 1 | D16: ='UT Lab 5'!C7 -> 2 | E16: ='UT Lab 5'!F7 -> 0 | F16: ='UT Lab 5'!L7 -> 3 | G16: ='UT Lab 5'!M7 -> 0 | H16: ='UT Lab 5'!N7 -> 0 | I16: ='UT Lab 5'!O7 -> 3
A17: 6 | B17: UT Lab 6 | C17: ='UT Lab 6'!A7 -> 9 | D17: ='UT Lab 6'!C7 -> 1 | E17: ='UT Lab 6'!F7 -> 0 | F17: ='UT Lab 6'!L7 -> 10 | G17: ='UT Lab 6'!M7 -> 0 | H17: ='UT Lab 6'!N7 -> 0 | I17: ='UT Lab 6'!O7 -> 10
A18: 7 | B18: UT Lab 7 | C18: ='UT Lab 7'!A7 -> 13 | D18: ='UT Lab 7'!C7 -> 0 | E18: ='UT Lab 7'!F7 -> 0 | F18: ='UT Lab 7'!L7 -> 13 | G18: ='UT Lab 7'!M7 -> 0 | H18: ='UT Lab 7'!N7 -> 0 | I18: ='UT Lab 7'!O7 -> 13
A19: 8 | B19: UT Lab 8 | C19: ='UT Lab 8'!A7 -> 6 | D19: ='UT Lab 8'!C7 -> 0 | E19: ='UT Lab 8'!F7 -> 0 | F19: ='UT Lab 8'!L7 -> 6 | G19: ='UT Lab 8'!M7 -> 0 | H19: ='UT Lab 8'!N7 -> 0 | I19: ='UT Lab 8'!O7 -> 6
A20: 9 | B20: UT Lab 9 | C20: ='UT Lab 9'!A7 -> 7 | D20: ='UT Lab 9'!C7 -> 0 | E20: ='UT Lab 9'!F7 -> 0 | F20: ='UT Lab 9'!L7 -> 7 | G20: ='UT Lab 9'!M7 -> 0 | H20: ='UT Lab 9'!N7 -> 0 | I20: ='UT Lab 9'!O7 -> 7
A21: 10 | B21: UT Lab10 | C21: ='UT Lab10'!A7 -> 1 | D21: ='UT Lab10'!C7 -> 2 | E21: ='UT Lab10'!F7 -> 0 | F21: ='UT Lab10'!L7 -> 3 | G21: ='UT Lab10'!M7 -> 0 | H21: ='UT Lab10'!N7 -> 0 | I21: ='UT Lab10'!O7 -> 3
A22: 11 | B22: UT Lab11 | C22: ='UT Lab11'!A7 -> 7 | D22: ='UT Lab11'!C7 -> 0 | E22: ='UT Lab11'!F7 -> 0 | F22: ='UT Lab11'!L7 -> 7 | G22: ='UT Lab11'!M7 -> 0 | H22: ='UT Lab11'!N7 -> 0 | I22: ='UT Lab11'!O7 -> 7
B24: Sub total | C24: =SUM(C10:C23) -> 56 | D24: =SUM(D10:D23) -> 15 | E24: =SUM(E10:E23) -> 0 | F24: =SUM(F10:F23) -> 71 | G24: =SUM(G10:G23) -> 0 | H24: =SUM(H10:H23) -> 0 | I24: =SUM(I10:I23) -> 71
B26: Test coverage | D26: =(C24+D24)*100/(I24) -> 100 | E26: %
B27: Test successful coverage | D27: =C24*100/(I24) -> 78.873239 | E27: %
B28: Normal case | D28: =F24*100/I24 -> 100 | E28: %
B29: Abnormal case | D29: =G24*100/I24 -> 0 | E29: %
B30: Boundary case | D30: =H24*100/I24 -> 0 | E30: %

Sheet UT Lab 1
A2: Function Code | C2: AUTH | F2: Function Name | L2: Login/Logout
A3: Created By | C3: Nhóm 10 | F3: Executed By | L3: Phạm Như Ý
A4: Lines of code | F4: Lack of test cases
A5: Test requirement | C5: Kiểm chứng đăng nhập, đăng xuất, token và route bảo vệ
A6: Passed | C6: Failed | F6: Untested | L6: N/A/B | O6: Total Test Cases
A7: =COUNTIF(F46:HQ46,"P") -> 9 | C7: =COUNTIF(F46:HQ46,"F") -> 0 | F7: =SUM(O7,-A7,-C7) -> 0 | L7: =COUNTIF(E45:HQ45,"N") -> 9 | M7: =COUNTIF(E45:HQ45,"A") -> 0 | N7: =COUNTIF(E45:HQ45,"B") -> 0 | O7: =COUNTA(E9:HT9) -> 9
F9: UTCID01 | G9: UTCID02 | H9: UTCID03 | I9: UTCID04 | J9: UTCID05 | K9: UTCID06 | L9: UTCID07 | M9: UTCID08 | N9: UTCID09
A10: Condition | B10: Precondition
D11: Đăng nhập
B12: Input
C13: Email
D14: "" | F14: O
D15: abc@ | G15: O
D16: emailkhonghople | H16: O
D17: nhuy02042003@gmail | I17: O
D18: notfound@example.com | J18: O
D19: linhMatL@gmail | K19: O
D20: linhMatL@gmail@com | L20: O
D21: mon02050703@gmail.com | M21: O
D22: nhuy02042003@gmail.com | N22: O
C24: Mật khẩu
D25: 123 | F25: O
D26: "" | G26: O
D27: 3333333333333333333333333 | H27: O
D28: 123978 | I28: O
D29: 12345# | J29: O
D30: 123456 | K30: O
D31: 123456 | L31: O
D32: 123456 | M32: O
D33: 123456 | N33: O
A34: Confirm | B34: Return
D35: success | M35: O | N35: O
D36: fail | F36: O | G36: O | H36: O | I36: O | J36: O | K36: O
B37: Exception
B39: Log message
D40: success | M40: O | N40: O
D41: Email là bắt buộc | F41: O
D42: mật khẩu không được chứa kí tự đặc biệt | J42: O
D43: mật khẩu là bắt buộc | G43: O
D44: Thông tin đăng nhập không chính xác | H44: O | I44: O | K44: O | L44: O
...

Sheet UT Lab 2
A2: Function Code | C2: REGISTER | F2: Function Name | L2: Register OTP
A3: Created By | C3: Nhóm 10 | F3: Executed By | L3: Phạm Như Ý
A4: Lines of code | F4: Lack of test cases
A5: Test requirement | C5: Kiểm chứng đăng ký tài khoản, OTP, validate email/mật khẩu
A6: Passed | C6: Failed | F6: Untested | L6: N/A/B | O6: Total Test Cases
A7: =COUNTIF(F32:HQ32,"P") -> 1 | C7: =COUNTIF(F32:HQ32,"F") -> 6 | F7: =SUM(O7,-A7,-C7) -> 0 | L7: =COUNTIF(E31:HQ31,"N") -> 7 | M7: =COUNTIF(E31:HQ31,"A") -> 0 | N7: =COUNTIF(E31:HQ31,"B") -> 0 | O7: =COUNTA(E9:HT9) -> 7
F9: UTCID01 | G9: UTCID02 | H9: UTCID03 | I9: UTCID04 | J9: UTCID05 | K9: UTCID06 | L9: UTCID07
A10: Condition | B10: Precondition
B12: Input
C13: Email
D14: "" | F14: O
D15: aaaaaaaaaaaaf | G15: O
D16: 023 | H16: O
D17: monne0205gmail.com | I17: O
D18: monne0205@gmail | J18: O
D19: nhuy02042003@gmail.com | K19: O
D20: monne0205@gmail.com | L20: O
A22: Confirm | B22: Return
D23: Email hợp lệ đăng ký thành công | L23: O
D24: Email không hợp lệ hoặc email đã tồn tại | F24: O | G24: O | H24: O | I24: O | J24: O | K24: O
B25: Exception
B27: Log message
D29: Mã OTP xác thực sẽ được gửi đến email | F29: O | G29: O | H29: O | I29: O | J29: O | K29: O | L29: O
D30: Email không hợp lệ hoặc email đã tồn tại
A31: Result | B31: Type(N : Normal, A : Abnormal, B : Boundary) | F31: N | G31: N | H31: N | I31: N | J31: N | K31: N | L31: N
B32: Passed/Failed | F32: F | G32: F | H32: F | I32: F | J32: F | K32: F | L32: P
B33: Executed Date | F33: 44165 | G33: 44165 | H33: 44165 | I33: 44165 | J33: 44165 | K33: 44165 | L33: 44165
B34: Defect ID

Sheet UT Lab 3
A2: Function Code | C2: PASSWORD | F2: Function Name | L2: Forgot/Reset Password
A3: Created By | C3: Nhóm 10 | F3: Executed By | L3: Phạm Như Ý
A4: Lines of code | F4: Lack of test cases
A5: Test requirement | C5: Kiểm chứng quên mật khẩu, reset mật khẩu và lỗi token
A6: Passed | C6: Failed | F6: Untested | L6: N/A/B | O6: Total Test Cases
A7: =COUNTIF(F28:HQ28,"P") -> 1 | C7: =COUNTIF(F28:HQ28,"F") -> 2 | F7: =SUM(O7,-A7,-C7) -> 0 | L7: =COUNTIF(E27:HQ27,"N") -> 3 | M7: =COUNTIF(E27:HQ27,"A") -> 0 | N7: =COUNTIF(E27:HQ27,"B") -> 0 | O7: =COUNTA(E9:HT9) -> 3
F9: UTCID01 | G9: UTCID02 | H9: UTCID03
A10: Condition | B10: Precondition
B12: Input
C13: input
D14: =TRUE() -> TRUE | F14: O
D15: TRUE | G15: O
D16: TRUE | H16: O
A18: Confirm | B18: Return
D19: Đã xóa người dùng | F19: O
B20: Exception
D21: Lỗi không tiếp cận được server | G21: O
D22: Lỗi đường truyền | H22: O
B23: Log message
D24: Đã xóa người dùng | G24: O
D25: Xóa không thành công | H25: O
A27: Result | B27: Type(N : Normal, A : Abnormal, B : Boundary) | F27: N | G27: N | H27: N
B28: Passed/Failed | F28: P | G28: F | H28: F
B29: Executed Date | F29: 44165 | G29: 44165 | H29: 44165
B30: Defect ID

Sheet UT Lab 4
A2: Function Code | C2: PROFILE | F2: Function Name | L2: Profile Management
A3: Created By | C3: Nhóm 10 | F3: Executed By | L3: Phạm Như Ý
A4: Lines of code | F4: Lack of test cases
A5: Test requirement | C5: Kiểm chứng xem/cập nhật hồ sơ, avatar và đổi mật khẩu
A6: Passed | C6: Failed | F6: Untested | L6: N/A/B | O6: Total Test Cases
A7: =COUNTIF(F27:HQ27,"P") -> 1 | C7: =COUNTIF(F27:HQ27,"F") -> 2 | F7: =SUM(O7,-A7,-C7) -> 0 | L7: =COUNTIF(E26:HQ26,"N") -> 3 | M7: =COUNTIF(E26:HQ26,"A") -> 0 | N7: =COUNTIF(E26:HQ26,"B") -> 0 | O7: =COUNTA(E9:HT9) -> 3
F9: UTCID01 | G9: UTCID02 | H9: UTCID03
A10: Condition | B10: Precondition
D11: Đăng nhập
B12: Input
D13: =TRUE() -> TRUE | F13: O
D14: TRUE | G14: O
D15: TRUE | H15: O
A17: Confirm | B17: Return
D18: Đã khóa người dùng | F18: O
B19: Exception
D20: Lỗi không tiếp cận được server | G20: O
D21: Lỗi đường truyền | H21: O
B22: Log message
D23: Đã khóa người dùng | F23: O
D24: Khóa không thành công | G24: O | H24: O
A26: Result | B26: Type(N : Normal, A : Abnormal, B : Boundary) | F26: N | G26: N | H26: N
B27: Passed/Failed | F27: P | G27: F | H27: F
B28: Executed Date | F28: 44165 | G28: 44165 | H28: 44165
B29: Defect ID

Sheet UT Lab 5
A2: Function Code | C2: FRIEND | F2: Function Name | L2: Friend Management
A3: Created By | C3: Nhóm 10 | F3: Executed By | L3: Phạm Như Ý
A4: Lines of code | F4: Lack of test cases
A5: Test requirement | C5: Kiểm chứng tìm kiếm bạn bè, gửi/chấp nhận/từ chối/xóa lời mời
A6: Passed | C6: Failed | F6: Untested | L6: N/A/B | O6: Total Test Cases
A7: =COUNTIF(F27:HQ27,"P") -> 1 | C7: =COUNTIF(F27:HQ27,"F") -> 2 | F7: =SUM(O7,-A7,-C7) -> 0 | L7: =COUNTIF(E26:HQ26,"N") -> 3 | M7: =COUNTIF(E26:HQ26,"A") -> 0 | N7: =COUNTIF(E26:HQ26,"B") -> 0 | O7: =COUNTA(E9:HT9) -> 3
F9: UTCID01 | G9: UTCID02 | H9: UTCID03
A10: Condition | B10: Precondition
D11: Đăng nhập
B12: Input
D13: =FALSE() -> FALSE | F13: O
D14: =FALSE() -> FALSE | G14: O
D15: =FALSE() -> FALSE | H15: O
A17: Confirm | B17: Return
D18: Đã mở khóa người dùng | F18: O
B19: Exception
D20: Lỗi không tiếp cận được server | G20: O
D21: Lỗi đường truyền | H21: O
B22: Log message
D23: Đã mở khóa người dùng | F23: O
D24: Mở khóa không thành công | G24: O | H24: O
A26: Result | B26: Type(N : Normal, A : Abnormal, B : Boundary) | F26: N | G26: N | H26: N
B27: Passed/Failed | F27: P | G27: F | H27: F
B28: Executed Date | F28: 44165 | G28: 44165 | H28: 44165
B29: Defect ID

Sheet UT Lab 6
A2: Function Code | C2: CHAT_PRIVATE | F2: Function Name | L2: Private Chat
A3: Created By | C3: Nhóm 10 | F3: Executed By | L3: Phạm Như Ý
A4: Lines of code | F4: Lack of test cases
A5: Test requirement | C5: Kiểm chứng nhắn tin 1-1, tạo conversation, realtime socket và trạng thái tin nhắn
A6: Passed | C6: Failed | F6: Untested | L6: N/A/B | O6: Total Test Cases
A7: =COUNTIF(F98:HQ98,"P") -> 9 | C7: =COUNTIF(F98:HQ98,"F") -> 1 | F7: =SUM(O7,-A7,-C7) -> 0 | L7: =COUNTIF(E97:HQ97,"N") -> 10 | M7: =COUNTIF(E97:HQ97,"A") -> 0 | N7: =COUNTIF(E97:HQ97,"B") -> 0 | O7: =COUNTA(E9:HT9) -> 10
F9: UTCID01 | G9: UTCID02 | H9: UTCID03 | I9: UTCID04 | J9: UTCID05 | K9: UTCID06 | L9: UTCID07 | M9: UTCID08 | N9: UTCID09 | O9: UTCID10
A10: Condition | B10: Precondition
D11: Môi trường test: BE http://localhost:3000, FE Vite, MongoDB, Socket.IO. Tài khoản user: nhuy02042003@gmail.com / 123456; tài khoản admin/page admin: mon02050703@gmail.com / 123456.
D12: số điện thoại chỉ chứa kí tự 1 "+" ở đầu và lớn hơn 9 số
D13: đúng định dạng email
D14: chọn ngày sinh và không được vượt quá thời điểm hiện tại
D15: Chỉ được chọn giới tính là nam hoặc nữ
B16: Input
C17: Họ tên
D18: "" | F18: O
D19: %%! | G19: O
D20: 5465465 | H20: O
D21: trump | I21: O
D22: Nguyễn văn A | J22: O
D23: Cat Moiiiiiiiiiiiiiiiiiiiiiiiiiiiiiiiiiiiiiiiiiiiiiiiiiiiiiiiiiiiiiiiiiii | K23: O
D24: linhMatL@gmail.com | L24: O
D25: 0946581522 | M25: O
D26: linhMatL@gmail.com | N26: O
D27: Trần văn an | O27: O
C28: Số điện thoại
D29: "" | F29: O
D30: %%$$ | G30: O
D31: 123456798 | H31: O
D32: ++0123456798 | I32: O
D33: +0123456789 | J33: O
D34: nggf | K34: O
D35: 09465812ngj | L35: O
D36: 0946581522 | M36: O
D37: 09465+42136 | N37: O
D38: 0946824555 | O38: O
C39: email
D40: "" | F40: O
D41: @gmail.com | G41: O
D42: Test$$@gmail.com | H42: O
...

Sheet UT Lab 7
A2: Function Code | C2: CHAT_GROUP | F2: Function Name | L2: Group Chat
A3: Created By | C3: Nhóm 10 | F3: Executed By | L3: Phạm Như Ý
A4: Lines of code | F4: Lack of test cases
A5: Test requirement | C5: Kiểm chứng tạo nhóm, thêm/rời/xóa thành viên, nhắn tin nhóm và quyền nhóm
A6: Passed | C6: Failed | F6: Untested | L6: N/A/B | O6: Total Test Cases
A7: =COUNTIF(F41:HQ41,"P") -> 13 | C7: =COUNTIF(F41:HQ41,"F") -> 0 | F7: =SUM(O7,-A7,-C7) -> 0 | L7: =COUNTIF(E40:HQ40,"N") -> 13 | M7: =COUNTIF(E40:HQ40,"A") -> 0 | N7: =COUNTIF(E40:HQ40,"B") -> 0 | O7: =COUNTA(E9:HT9) -> 13
F9: UTCID01 | G9: UTCID02 | H9: UTCID03 | I9: UTCID04 | J9: UTCID05 | K9: UTCID06 | L9: UTCID07 | M9: UTCID08 | N9: UTCID09 | O9: UTCID10 | P9: UTCID11 | Q9: UTCID12 | R9: UTCID13
A10: Condition | B10: Precondition
D11: Môi trường test: BE http://localhost:3000, FE Vite, MongoDB, Socket.IO. Tài khoản user: nhuy02042003@gmail.com / 123456; tài khoản admin/page admin: mon02050703@gmail.com / 123456.
B12: Input
C13: Thanh tìm kiếm
D14: "" | F14: O
D15: 01 | G15: O
D16: a | H16: O
D17: 013546798? | I17: O
D18: 0123456789 | J18: O
D19: @ | K19: O
D20: 0946581524 | L20: O
D21: Nguyễn | M21: O
D22: Nguyễn Danh Minh Toàn | N22: O
D23: NG555555555555555555555555555555555555555555555555551111111111111 | O23: O
D24: True | P24: O
D25: Nam | Q25: O
D26: 01/02/1999 | R26: O
A28: Confirm | B28: Return
D29: Không tìm thấy | F29: O | I29: O | J29: O | O29: O | P29: O
D30: Trả về danh sách giá trị | G30: O | H30: O | K30: O | M30: O | Q30: O
D31: Trả về được một giá trị | L31: O | N31: O | R31: O
B32: Exception
B34: Log message
D35: Không tìm thấy | M35: O | N35: O | O35: O | P35: O
D36: Danh sách người dùng | F36: O | Q36: O
D37: Một người dùng | J37: O | R37: O
G38: O
H39: O | I39: O | K39: O | L39: O
A40: Result | B40: Type(N : Normal, A : Abnormal, B : Boundary) | F40: N | G40: N | H40: N | I40: N | J40: N | K40: N | L40: N | M40: N | N40: N | O40: N | P40: N | Q40: N | R40: N
B41: Passed/Failed | F41: P | G41: P | H41: P | I41: P | J41: P | K41: P | L41: P | M41: P | N41: P | O41: P | P41: P | Q41: P | R41: P
B42: Executed Date | F42: 44165 | G42: 44165 | H42: 44165 | I42: 44165 | J42: 44165 | K42: 44165 | L42: 44165 | M42: 44165 | N42: 44165 | O42: 44165 | P42: 44165 | Q42: 44165 | R42: 44165
B43: Defect ID

Sheet UT Lab 8
A2: Function Code | C2: FILE_FORWARD | F2: Function Name | L2: File & Forward
A3: Created By | C3: Nhóm 10 | F3: Executed By | L3: Phạm Như Ý
A4: Lines of code | C4: 36 | F4: Lack of test cases | L4: 6
A5: Test requirement | C5: Kiểm chứng gửi file/hình ảnh và chuyển tiếp tin nhắn/file
A6: Passed | C6: Failed | F6: Untested | L6: N/A/B | O6: Total Test Cases
A7: =COUNTIF(F42:HQ42,"P") -> 6 | C7: =COUNTIF(F42:HQ42,"F") -> 0 | F7: =SUM(O7,-A7,-C7) -> 0 | L7: =COUNTIF(E41:HQ41,"N") -> 6 | M7: =COUNTIF(E41:HQ41,"A") -> 0 | N7: =COUNTIF(E41:HQ41,"B") -> 0 | O7: =COUNTA(E9:HT9) -> 6
F9: UTCID01 | G9: UTCID02 | H9: UTCID03 | I9: UTCID04 | J9: UTCID05 | K9: UTCID06
A10: Condition | B10: Precondition
D11: Môi trường test: BE http://localhost:3000, FE Vite, MongoDB, Socket.IO. Tài khoản user: nhuy02042003@gmail.com / 123456; tài khoản admin/page admin: mon02050703@gmail.com / 123456.
B12: Input
C13: User
D14: Email
D15: "" | F15: O
D16: abc@ | G16: O
D17: monne0205@gmail.com | H17: O
D18: monne0205gmail.com | I18: O
D19: monne0205@gmail | J19: O
D20: monne0205@gmail .com | K20: O
D21: mật khẩu
D22: "" | F22: O
D23: 123 | G23: O
D24: nhuy123 | H24: O
D25: 123 | I25: O
D26: admin | J26: O
D27: bien@123 | K27: O
A30: Confirm | B30: Return
D31: success | H31: O
D32: fail | F32: O | G32: O | I32: O | J32: O | K32: O
B33: Exception
B35: Log message
D36: Đăng kí thành công | H36: O
D37: Email là bắt buộc | F37: O
D38: Email không đúng định dạng | G38: O | I38: O
D39: Mật khẩu quá ngắn | J39: O
D40: Mật khẩu không được chứa kí tự đặc biệt | K40: O
A41: Result | B41: Type(N : Normal, A : Abnormal, B : Boundary) | F41: N | G41: N | H41: N | I41: N | J41: N | K41: N
B42: Passed/Failed | F42: P | G42: P | H42: P | I42: P | J42: P | K42: P
B43: Executed Date | F43: 44165 | G43: 44165 | H43: 44165 | I43: 44165 | J43: 44165 | K43: 44165
B44: Defect ID

Sheet UT Lab 9
A2: Function Code | C2: CALL | F2: Function Name | L2: Audio/Video Call
A3: Created By | C3: Nhóm 10 | F3: Executed By | L3: Phạm Như Ý
A4: Lines of code | C4: 52 | F4: Lack of test cases
A5: Test requirement | C5: Kiểm chứng gọi audio/video 1-1, group call, accept/reject/end và TURN/STUN
A6: Passed | C6: Failed | F6: Untested | L6: N/A/B | O6: Total Test Cases
A7: =COUNTIF(F42:HQ42,"P") -> 7 | C7: =COUNTIF(F42:HQ42,"F") -> 0 | F7: =SUM(O7,-A7,-C7) -> 0 | L7: =COUNTIF(E41:HQ41,"N") -> 7 | M7: =COUNTIF(E41:HQ41,"A") -> 0 | N7: =COUNTIF(E41:HQ41,"B") -> 0 | O7: =COUNTA(E9:HT9) -> 7
F9: UTCID01 | G9: UTCID02 | H9: UTCID03 | I9: UTCID04 | J9: UTCID05 | K9: UTCID06 | L9: UTCID07
A10: Condition | B10: Precondition
D11: Môi trường test: BE http://localhost:3000, FE Vite, MongoDB, Socket.IO. Tài khoản user: nhuy02042003@gmail.com / 123456; tài khoản admin/page admin: mon02050703@gmail.com / 123456.
B12: Input
C13: key | D13: key of a user
C14: oldPassword
D15: "" | F15: O
D16: 049122 | G16: O
D17: aa@ff | H17: O
D18: 0156 | I18: O
D19: nhuy123 | J19: O
D20: 123456 | K20: O
D21: 123456 | L21: O
C22: newPassword
D23: "" | G23: O
D24: "" | H24: O
D25: nhuy123 | I25: O
D26: nhuy123 | J26: O
D27: nhuy123 | K27: O
D28: 123456 | L28: O
A30: Confirm | B30: Return
D31: success | K31: O
D32: fail | F32: O | G32: O | H32: O | I32: O | J32: O | L32: O
B33: Exception
B35: Log message
D36: Đổi mật khẩu thành công | K36: O
D37: hãy nhập mật khẩu cũ | F37: O
D38: hãy nhập mật khẩu mới | G38: O
D39: Mật khẩu mới không được trùng mật khẩu cũ | H39: O | I39: O | J39: O | L39: O
A41: Result | B41: Type(N : Normal, A : Abnormal, B : Boundary) | F41: N | G41: N | H41: N | I41: N | J41: N | K41: N | L41: N
B42: Passed/Failed | F42: P | G42: P | H42: P | I42: P | J42: P | K42: P | L42: P
B43: Executed Date | F43: 44165 | G43: 44165 | H43: 44165 | I43: 44165 | J43: 44165 | K43: 44165 | L43: 44165
B44: Defect ID

Sheet UT Lab10
A2: Function Code | C2: AI_CHAT | F2: Function Name | L2: Public Service AI
A3: Created By | C3: Nhóm 10 | F3: Executed By | L3: Phạm Như Ý
A4: Lines of code | C4: 30 | F4: Lack of test cases
A5: Test requirement | C5: Kiểm chứng Chat AI dịch vụ công, xử lý câu hỏi ngắn, lỗi Gemini và fallback
A6: Passed | C6: Failed | F6: Untested | L6: N/A/B | O6: Total Test Cases
A7: =COUNTIF(F30:HQ30,"P") -> 1 | C7: =COUNTIF(F30:HQ30,"F") -> 2 | F7: =SUM(O7,-A7,-C7) -> 0 | L7: =COUNTIF(E29:HQ29,"N") -> 3 | M7: =COUNTIF(E29:HQ29,"A") -> 0 | N7: =COUNTIF(E29:HQ29,"B") -> 0 | O7: =COUNTA(E9:HT9) -> 3
F9: UTCID01 | G9: UTCID02 | H9: UTCID03
A10: Condition | B10: Precondition
D11: Môi trường test: BE http://localhost:3000, FE Vite, MongoDB, Socket.IO. Tài khoản user: nhuy02042003@gmail.com / 123456; tài khoản admin/page admin: mon02050703@gmail.com / 123456.
B12: Input
C13: key | D13: key of a user | F13: O
D14: null | G14: O | H14: O
B16: Output
D17: Password = "123456" | F17: O | H17: O
D18: Password = oldPassword | G18: O | H18: O
A20: Confirm | B20: Return
D21: success | F21: O
D22: fail | G22: O | H22: O
B23: Exception
D24: đường truyền bị gián đoạn | G24: O
B25: Log message
D26: Cập nhật lại mật khẩu thành công
D27: không lấy được thông tin người dùng | F27: O | H27: O
A29: Result | B29: Type(N : Normal, A : Abnormal, B : Boundary) | F29: N | G29: N | H29: N
B30: Passed/Failed | F30: P | G30: F | H30: F
B31: Executed Date | F31: 44165 | G31: 44165 | H31: 44165
B32: Defect ID

Sheet UT Lab11
A2: Function Code | C2: ADMIN | F2: Function Name | L2: Admin Management
A3: Created By | C3: Nhóm 10 | F3: Executed By | L3: Phạm Như Ý
A4: Lines of code | C4: 70 | F4: Lack of test cases
A5: Test requirement | C5: Kiểm chứng admin dashboard, quản lý user, group, thống kê, khóa/xóa
A6: Passed | C6: Failed | F6: Untested | L6: N/A/B | O6: Total Test Cases
A7: =COUNTIF(F53:HQ53,"P") -> 7 | C7: =COUNTIF(F53:HQ53,"F") -> 0 | F7: =SUM(O7,-A7,-C7) -> 0 | L7: =COUNTIF(E52:HQ52,"N") -> 7 | M7: =COUNTIF(E52:HQ52,"A") -> 0 | N7: =COUNTIF(E52:HQ52,"B") -> 0 | O7: =COUNTA(E9:HT9) -> 7
F9: UTCID01 | G9: UTCID02 | H9: UTCID03 | I9: UTCID04 | J9: UTCID05 | K9: UTCID06 | L9: UTCID07
A10: Condition | B10: Precondition
D11: Môi trường test: BE http://localhost:3000, FE Vite, MongoDB, Socket.IO. Tài khoản user: nhuy02042003@gmail.com / 123456; tài khoản admin/page admin: mon02050703@gmail.com / 123456.
B12: Input
C13: key | D13: key of a UserAccount (ID)
C14: Gender | D14: is only male or female
C15: name
D16: "" | F16: O
D17: 049122 | G17: O
D18: aa@ff | H18: O
D19: 0156 | I19: O
D20: NhuY123 | J20: O
D21: Phạm Như Ý | K21: O
D22: Nguyễn Danh Minh Toàn | L22: O
C23: link img
D24: a1.png | F24: O
D25: "" | G25: O
D26: a2.png | H26: O
D27: a3.png | I27: O
D28: a4.png | J28: O
D29: a5.png | K29: O
D30: a1.pnr | L30: O
C31: date birth
D32: 17/12/2020 | F32: O
D33: 17/11/2019 | G33: O
D34: 07/10/1999 | H34: O
D35: 07/10/1999 | I35: O
D36: 07/10/1999 | J36: O
D37: 07/10/1999 | K37: O
D38: 15/1/1999 | L38: O
B39: Output | C39: User
A41: Confirm | B41: Return
D42: success | K42: O | L42: O
D43: fail | F43: O | G43: O | H43: O | I43: O | J43: O
...

Sheet Full Test Cases
A1: TC ID | B1: Module | C1: Feature | D1: Test case | E1: Type | F1: Priority | G1: Precondition | H1: Test data | I1: Steps | J1: Expected result | K1: Tester | L1: Execution | M1: Status | N1: Note
A2: AUTH-001 | B2: Authentication | C2: Login | D2: Dang nhap thanh cong bang email hop le | E2: Normal | F2: High | G2: BE va DB dang chay, tai khoan ton tai | H2: nhuy02042003@gmail.com / 123456 | I2: 1. Mo trang login; 2. Nhap email va mat khau; 3. Bam Dang nhap | J2: Dang nhap thanh cong, vao trang chat, token duoc luu | K2: Pham Nhu Y | L2: Individual | M2: Not Run
A3: AUTH-002 | B3: Authentication | C3: Login | D3: Dang nhap thanh cong bang tai khoan thu hai | E3: Normal | F3: High | G3: Tai khoan ton tai | H3: nhuy02042003@gmail.com / 123456 | I3: 1. Nhap thong tin; 2. Bam Dang nhap | J3: Dang nhap thanh cong va hien thi dung thong tin user | K3: Pham Nhu Y | L3: Individual | M3: Not Run
A4: AUTH-003 | B4: Authentication | C4: Login | D4: Dang nhap bang tai khoan admin/page admin | E4: Normal | F4: High | G4: Tai khoan ton tai | H4: mon02050703@gmail.com / 123456 | I4: 1. Nhap thong tin; 2. Bam Dang nhap | J4: Dang nhap thanh cong, co quyen truy cap trang admin | K4: Pham Nhu Y | L4: Individual | M4: Not Run | N4: Email da chuan hoa bo khoang trang
A5: AUTH-004 | B5: Authentication | C5: Login | D5: Sai mat khau | E5: Abnormal | F5: High | G5: Tai khoan ton tai | H5: nhuy02042003@gmail.com / 1234567 | I5: 1. Nhap sai password; 2. Bam Dang nhap | J5: Thong bao loi, khong tao session | K5: Pham Nhu Y | L5: Individual | M5: Not Run
A6: AUTH-005 | B6: Authentication | C6: Login | D6: Email khong ton tai | E6: Abnormal | F6: Medium | G6: Khong co user trong DB | H6: notfound@example.com / 123456 | I6: 1. Nhap email la; 2. Bam Dang nhap | J6: Thong bao email hoac mat khau khong dung | K6: Pham Nhu Y | L6: Individual | M6: Not Run
A7: AUTH-006 | B7: Authentication | C7: Login | D7: Bo trong email | E7: Boundary | F7: Medium | G7: Trang login san sang | H7: (blank) / 123456 | I7: 1. De trong email; 2. Bam Dang nhap | J7: Validate bat buoc nhap email | K7: Pham Nhu Y | L7: Individual | M7: Not Run
A8: AUTH-007 | B8: Authentication | C8: Login | D8: Bo trong password | E8: Boundary | F8: Medium | G8: Trang login san sang | H8: nhuy02042003@gmail.com / blank | I8: 1. De trong mat khau; 2. Bam Dang nhap | J8: Validate bat buoc nhap mat khau | K8: Pham Nhu Y | L8: Individual | M8: Not Run
A9: AUTH-008 | B9: Authentication | C9: Logout | D9: Dang xuat | E9: Normal | F9: Medium | G9: Da dang nhap | H9: Tai khoan bat ky | I9: 1. Bam dang xuat | J9: Token bi xoa, ve trang login | K9: Pham Nhu Y | L9: Individual | M9: Not Run
A10: REG-001 | B10: Register | C10: Send OTP | D10: Gui OTP dang ky email moi | E10: Normal | F10: High | G10: Email chua ton tai | H10: monne0205@gmail.com | I10: 1. Nhập email monne0205@gmail.com; 2. Bấm gửi OTP | J10: Hệ thống gửi OTP qua email và hiển thị trang nhập OTP | K10: Pham Nhu Y | L10: Individual | M10: Not Run
A11: REG-002 | B11: Register | C11: Send OTP | D11: Email sai dinh dang | E11: Abnormal | F11: Medium | G11: Trang dang ky san sang | H11: abc@ | I11: 1. Nhap email sai; 2. Gui OTP | J11: Thong bao email khong hop le | K11: Pham Nhu Y | L11: Individual | M11: Not Run
A12: REG-003 | B12: Register | C12: Verify OTP | D12: Nhap OTP sai | E12: Abnormal | F12: Medium | G12: Da gui OTP | H12: OTP 000000 | I12: 1. Nhap OTP sai; 2. Xac nhan | J12: Thong bao OTP khong dung | K12: Pham Nhu Y | L12: Individual | M12: Not Run
A13: REG-004 | B13: Register | C13: Verify OTP | D13: Dang ky thanh cong | E13: Normal | F13: High | G13: Co OTP hop le | H13: monne0205@gmail.com, username, password 123456 | I13: 1. Nhap OTP dung; 2. Nhap thong tin; 3. Hoan tat | J13: Tạo user mới bằng email monne0205@gmail.com và cho đăng nhập | K13: Pham Nhu Y | L13: Individual | M13: Not Run
A14: PASS-001 | B14: Password | C14: Forgot password | D14: Gui OTP quen mat khau | E14: Normal | F14: High | G14: Email ton tai | H14: nhuy02042003@gmail.com | I14: 1. Mo quen mat khau; 2. Nhap email | J14: Gui OTP reset password | K14: Pham Nhu Y | L14: Individual | M14: Not Run
A15: PASS-002 | B15: Password | C15: Forgot password | D15: Email khong ton tai | E15: Abnormal | F15: Medium | G15: Email khong co trong DB | H15: unknown@test.com | I15: 1. Nhap email; 2. Gui | J15: Thong bao email khong ton tai | K15: Pham Nhu Y | L15: Individual | M15: Not Run
A16: PASS-003 | B16: Password | C16: Reset password | D16: OTP reset sai | E16: Abnormal | F16: Medium | G16: Da gui OTP | H16: OTP sai | I16: 1. Nhap OTP sai; 2. Xac nhan | J16: Thong bao OTP khong hop le | K16: Pham Nhu Y | L16: Individual | M16: Not Run
... A23: FRIEND-002 | B23: Friend | C23: Search friend | D23: Tim email khong ton tai | E23: Abnormal | F23: Low | G23: Da dang nhap | H23: notfound@test.com | I23: 1. Tim email | J23: Thong bao khong tim thay | K23: Pham Nhu Y | L23: Individual | M23: Not Run
A24: FRIEND-003 | B24: Friend | C24: Request | D24: Gui loi moi ket ban | E24: Normal | F24: High | G24: Hai tai khoan chua la ban | H24: Account A gui cho B | I24: 1. A tim B; 2. Gui ket ban | J24: B nhan loi moi realtime | K24: Pham Nhu Y | L24: Group | M24: Not Run | N24: Can 2 tai khoan cung luc
A25: FRIEND-004 | B25: Friend | C25: Accept request | D25: Chap nhan ket ban | E25: Normal | F25: High | G25: B co loi moi tu A | H25: A va B | I25: 1. B vao loi moi; 2. Dong y | J25: Ca 2 thanh ban, conversation duoc tao | K25: Pham Nhu Y | L25: Group | M25: Not Run | N25: Can 2 tai khoan
A26: FRIEND-005 | B26: Friend | C26: Reject request | D26: Tu choi ket ban | E26: Abnormal | F26: Medium | G26: B co loi moi tu A | H26: A va B | I26: 1. B bam tu choi | J26: Trang thai request bi reject | K26: Pham Nhu Y | L26: Individual | M26: Not Run
A27: FRIEND-006 | B27: Friend | C27: Remove friend | D27: Huy ket ban nhung giu conversation | E27: Normal | F27: High | G27: Hai user da la ban | H27: A va B | I27: 1. A huy ket ban | J27: Khong nhan tin moi, lich su conversation van xem duoc | K27: Pham Nhu Y | L27: Group | M27: Not Run | N27: Can xac nhan ca hai phia
A28: CHAT-001 | B28: Private Chat | C28: Open conversation | D28: Bam ban be de mo chat 1-1 | E28: Normal | F28: High | G28: Da la ban | H28: Friend trong list | I28: 1. Vao danh sach ban; 2. Bam Nhan tin | J28: Box chat mo conversation private dung user | K28: Pham Nhu Y | L28: Individual | M28: Not Run
A29: CHAT-002 | B29: Private Chat | C29: Send message | D29: Gui tin nhan text 1-1 | E29: Normal | F29: High | G29: A va B la ban, cung online | H29: A: mon..., B: nhuy... | I29: 1. A gui tin; 2. B quan sat | J29: B nhan realtime, sidebar cap nhat last message | K29: Pham Nhu Y | L29: Group | M29: Not Run | N29: Can 2 nguoi test
A30: CHAT-003 | B30: Private Chat | C30: Receive unread | D30: Tin nhan den conversation chua mo hien badge | E30: Normal | F30: Medium | G30: B dang o conversation khac | H30: A gui tin cho B | I30: 1. A gui; 2. B xem sidebar | J30: Badge unread tang dung 1 | K30: Pham Nhu Y | L30: Group | M30: Not Run
A31: CHAT-004 | B31: Private Chat | C31: Edit message | D31: Sua tin nhan da gui | E31: Normal | F31: Medium | G31: User co tin text cua minh | H31: Tin text | I31: 1. Mo menu; 2. Sua; 3. Luu | J31: Noi dung cap nhat, hien da sua | K31: Pham Nhu Y | L31: Individual | M31: Not Run
A32: CHAT-005 | B32: Private Chat | C32: Unsend message | D32: Thu hoi tin nhan | E32: Normal | F32: Medium | G32: User co tin cua minh | H32: Tin text | I32: 1. Mo menu; 2. Thu hoi | J32: Tin hien trang thai da thu hoi cho ca 2 ben | K32: Pham Nhu Y | L32: Group | M32: Not Run
A33: CHAT-006 | B33: Private Chat | C33: Delete for me | D33: Xoa tin phia toi | E33: Normal | F33: Low | G33: Co tin trong conversation | H33: Tin bat ky | I33: 1. Chon xoa phia toi | J33: Tin an voi user hien tai, user kia van thay | K33: Pham Nhu Y | L33: Individual | M33: Not Run
A34: CHAT-007 | B34: Private Chat | C34: Reaction | D34: Tha reaction tin nhan | E34: Normal | F34: Low | G34: Co tin nhan | H34: Like/love | I34: 1. Hover tin; 2. Chon reaction | J34: Reaction hien dung va realtime | K34: Pham Nhu Y | L34: Group | M34: Not Run
A35: CHAT-008 | B35: Private Chat | C35: Reply | D35: Tra loi tin nhan | E35: Normal | F35: Medium | G35: Co tin nhan cu | H35: Reply text | I35: 1. Chon Tra loi; 2. Gui | J35: Tin moi co preview reply, click preview scroll ve tin goc | K35: Pham Nhu Y | L35: Individual | M35: Not Run
A36: CHAT-009 | B36: Private Chat | C36: Search message | D36: Tim tin nhan bang icon search | E36: Normal | F36: Medium | G36: Conversation co nhieu tin | H36: Keyword co trong tin | I36: 1. Bam icon search; 2. Nhap keyword | J36: Input hien, ket qua dung, click scroll den tin | K36: Pham Nhu Y | L36: Individual | M36: Not Run
A37: CHAT-010 | B37: Private Chat | C37: Blocked after unfriend | D37: Khong cho gui khi khong con la ban | E37: Abnormal | F37: High | G37: Da huy ket ban nhung con conversation | H37: A va B | I37: 1. Mo chat cu; 2. Thu gui tin | J37: Input bi khoa hoac API tu choi gui | K37: Pham Nhu Y | L37: Group | M37: Not Run
A38: GROUP-001 | B38: Group Chat | C38: Create group | D38: Tao nhom moi tu ban be | E38: Normal | F38: High | G38: Co it nhat 2 ban be | H38: Ten nhom, thanh vien | I38: 1. Bam tao nhom; 2. Chon thanh vien; 3. Tao | J38: Group conversation hien trong sidebar | K38: Pham Nhu Y | L38: Individual | M38: Not Run
A39: GROUP-002 | B39: Group Chat | C39: Send group message | D39: Gui tin nhan nhom | E39: Normal | F39: High | G39: Nhom co 3 thanh vien | H39: 3 tai khoan test | I39: 1. A gui tin nhom | J39: Tat ca thanh vien nhan realtime | K39: Pham Nhu Y | L39: Group | M39: Not Run | N39: Can 3 nguoi test
A40: GROUP-003 | B40: Group Chat | C40: Add member | D40: Them thanh vien vao nhom | E40: Normal | F40: Medium | G40: User la admin nhom | H40: Thanh vien moi | I40: 1. Mo thong tin nhom; 2. Them thanh vien | J40: Thanh vien moi thay nhom va lich su theo rule | K40: Pham Nhu Y | L40: Group | M40: Not Run
A41: GROUP-004 | B41: Group Chat | C41: Remove member | D41: Xoa thanh vien khoi nhom | E41: Normal | F41: Medium | G41: User la admin nhom | H41: Member can xoa | I41: 1. Admin xoa member | J41: Member bi xoa khong gui duoc tiep | K41: Pham Nhu Y | L41: Group | M41: Not Run
A42: GROUP-005 | B42: Group Chat | C42: Leave group | D42: Roi nhom | E42: Normal | F42: Medium | G42: User la member nhom | H42: Tai khoan member | I42: 1. Member bam roi nhom | J42: Nhom bien mat khoi sidebar user do | K42: Pham Nhu Y | L42: Individual | M42: Not Run
A43: GROUP-006 | B43: Group Chat | C43: Dissolve group | D43: Giai tan nhom | E43: Normal | F43: High | G43: User la admin nhom | H43: Group active | I43: 1. Admin giai tan | J43: Tat ca thanh vien thay nhom bi giai tan, khong gui duoc | K43: Pham Nhu Y | L43: Group | M43: Not Run
A44: GROUP-007 | B44: Group Chat | C44: Group search | D44: Tim tin nhan nhom bang icon search | E44: Normal | F44: Medium | G44: Nhom co nhieu tin | H44: Keyword | I44: 1. Bam icon search; 2. Nhap keyword | J44: Input hien giong chat 1-1, ket qua dung | K44: Pham Nhu Y | L44: Individual | M44: Not Run
A45: GROUP-008 | B45: Group Chat | C45: Group info | D45: Xem thong tin nhom | E45: Normal | F45: Low | G45: Nhom ton tai | H45: Group active | I45: 1. Bam Thong tin nhom | J45: Hien avatar, ten, thanh vien, quyen admin | K45: Pham Nhu Y | L45: Individual | M45: Not Run
A46: FILE-001 | B46: File Upload | C46: Image | D46: Gui anh trong chat 1-1 | E46: Normal | F46: Medium | G46: Conversation active | H46: File jpg/png < 10MB | I46: 1. Chon file; 2. Gui | J46: Anh hien trong chat, receiver xem duoc | K46: Pham Nhu Y | L46: Group | M46: Not Run
...
